Traceback (most recent call last):
  File "/Users/rebeccajohnson/opt/anaconda3/lib/python3.8/site-packages/jupyter_cache/executors/utils.py", line 51, in single_nb_execution
    executenb(
  File "/Users/rebeccajohnson/opt/anaconda3/lib/python3.8/site-packages/nbclient/client.py", line 1087, in execute
    return NotebookClient(nb=nb, resources=resources, km=km, **kwargs).execute()
  File "/Users/rebeccajohnson/opt/anaconda3/lib/python3.8/site-packages/nbclient/util.py", line 74, in wrapped
    return just_run(coro(*args, **kwargs))
  File "/Users/rebeccajohnson/opt/anaconda3/lib/python3.8/site-packages/nbclient/util.py", line 53, in just_run
    return loop.run_until_complete(coro)
  File "/Users/rebeccajohnson/opt/anaconda3/lib/python3.8/asyncio/base_events.py", line 616, in run_until_complete
    return future.result()
  File "/Users/rebeccajohnson/opt/anaconda3/lib/python3.8/site-packages/nbclient/client.py", line 540, in async_execute
    await self.async_execute_cell(
  File "/Users/rebeccajohnson/opt/anaconda3/lib/python3.8/site-packages/nbclient/client.py", line 832, in async_execute_cell
    self._check_raise_for_error(cell, exec_reply)
  File "/Users/rebeccajohnson/opt/anaconda3/lib/python3.8/site-packages/nbclient/client.py", line 740, in _check_raise_for_error
    raise CellExecutionError.from_cell_and_msg(cell, exec_reply['content'])
nbclient.exceptions.CellExecutionError: An error occurred while executing the following cell:
------------------
import pandas as pd
from IPython.display import display, HTML

grade_summary = pd.Data.Frame({Assignments:
                ["Datacamp modules",
                  "Two problem sets",
                  "Final project",
                  "Replication of another group's project",
                  "Team player/participation"],
                Percentage:
                [5, 
                  30,
                  45,
                  15, 5],
                Deadlines:
                ["Throughout",
                  "Pset one: Thurs. 04-15; \
                  Pset two: Thurs. 05-13",
                  "Presentation: Tuesday 06-01; Short paper: Friday 05-28",
                  "Sunday 06-06",
                  "Throughout"]}) 
                  
HTML(grade_summary.to_html(index=False))
        
------------------

[0;31m---------------------------------------------------------------------------[0m
[0;31mAttributeError[0m                            Traceback (most recent call last)
[0;32m<ipython-input-1-3fc7b0605764>[0m in [0;36m<module>[0;34m[0m
[1;32m      2[0m [0;32mfrom[0m [0mIPython[0m[0;34m.[0m[0mdisplay[0m [0;32mimport[0m [0mdisplay[0m[0;34m,[0m [0mHTML[0m[0;34m[0m[0;34m[0m[0m
[1;32m      3[0m [0;34m[0m[0m
[0;32m----> 4[0;31m grade_summary = pd.Data.Frame({Assignments:
[0m[1;32m      5[0m                 ["Datacamp modules",
[1;32m      6[0m                   [0;34m"Two problem sets"[0m[0;34m,[0m[0;34m[0m[0;34m[0m[0m

[0;32m~/opt/anaconda3/lib/python3.8/site-packages/pandas/__init__.py[0m in [0;36m__getattr__[0;34m(name)[0m
[1;32m    242[0m         [0;32mreturn[0m [0m_SparseArray[0m[0;34m[0m[0;34m[0m[0m
[1;32m    243[0m [0;34m[0m[0m
[0;32m--> 244[0;31m     [0;32mraise[0m [0mAttributeError[0m[0;34m([0m[0;34mf"module 'pandas' has no attribute '{name}'"[0m[0;34m)[0m[0;34m[0m[0;34m[0m[0m
[0m[1;32m    245[0m [0;34m[0m[0m
[1;32m    246[0m [0;34m[0m[0m

[0;31mAttributeError[0m: module 'pandas' has no attribute 'Data'
AttributeError: module 'pandas' has no attribute 'Data'

